Workbook
Name ChecklistTotal: SUM(#REF!)
Name ColumnTitle1: HealthReport!$B$27:$L$39
Name ColumnTitle2: #REF!
Name ColumnTitle3: #REF!
Name RowTitleRegion1..C7: HealthReport!$C$4
Name SchoolYear: YEAR(TODAY())&" - "&YEAR(TODAY())+1
Name SumItemsBought: COUNTIF(HealthReport!$L$27:$L$39,">0")
Name SumItemsToBuy: COUNTIF(HealthReport!$H$27:$H$39,">0")

Sheet HealthReport
C1: 健康检查报告 | F1: Health Report
C3: Server Info | H3: DataBase Info
C4: 主机名 | E4: rac19c1,rac19c2 | H4: 数据库名 | J4: APC2DB
C5: IP地址 | E5: 1.1.1.191 1.1.1.190 1.1.1.192 1.1.1.193 1.1.1.194 | H5: 数据库版本 | J5: Oracle Database 19c Enterprise
C6: 系统平台 | E6: Solaris[tm] OE (64-bit) | H6: 数据库架构 | J6: SINGLE INSTANCE
C7: 操作系统补丁 | E7: SunOS. Oracle Solaris 11.4 SPARC | H7: 主备库角色 | J7: PRIMARY,MAXIMUM PERFORMANCE | P7: =IFERROR(COUNTIFS(HealthReport!$H$27:$H$39,">0",HealthReport!$L$27:$L$39,">0")/SumItemsToBuy,0) -> 0
C8: CPU核数 | E8: 32 | H8: 是否开启归档 | J8: ARCHIVELOG
C9: CPU频率 | E9: 2800 | H9: 数据库字符集 | J9: AMERICAN_AMERICA.US7ASCII
C10: 内存 | E10: 260352 Megabytes | H10: 数据库总大小GB | J10: 1513.200 GB
C13: Issue summary | H13: ="Health status ("&COUNTIFS(HealthReport!$L$27:$L$39, ">0")&" of "&COUNTIFS(HealthReport!$H$27:$H$39, ">0")&")" -> Health status (0 of 0)
D14: 重要 | E14: 普通 | F14: 轻微
C15: 主机系统分析 | D15: 3 | E15: 5 | F15: 1
C16: 数据库实例分析 | D16: 5 | E16: 5 | F16: 5
C17: 数据库集群检查 | D17: 1 | E17: 0 | F17: 0
C18: DataGuard检查 | D18: 0 | E18: 0 | F18: 0
C19: 数据库备份检查 | D19: 0 | E19: 0 | F19: 0
C20: 数据库安全检查 | D20: 0 | E20: 0 | F20: 0
C21: 软件使用分析 | D21: 0 | E21: 0 | F21: 0
C22: 其他项检查 | D22: 0 | E22: 0 | F22: 0
C25: Issue list
B26: No. | C26: 问题类别 | D26: 检查项 | F26: 结果 | G26: 影响 | H26: 问题描述及建议 | L26: =SUM(HealthReport!$F$27:$F$39)/130 -> 0.52307692
B27: 1 | C27: 主机系统分析 | D27: CPU负载检查 | F27: 10 | G27: {=_xlfn.IFS(HealthReport!$F27>=10,"PASS",HealthReport!$F27=8,"轻微",HealthReport!$F27=5,"普通",HealthReport!$F27=0,"重要")} -> PASS
B28: 2 | C28: 主机系统分析 | D28: 内存使用检查 | F28: 10 | G28: {=_xlfn.IFS(HealthReport!$F28>=10,"PASS",HealthReport!$F28=8,"轻微",HealthReport!$F28=5,"普通",HealthReport!$F28=0,"重要")} -> PASS
B29: 3 | C29: 主机系统分析 | D29: 磁盘IO负载检查 | F29: 10 | G29: {=_xlfn.IFS(HealthReport!$F29>=10,"PASS",HealthReport!$F29=8,"轻微",HealthReport!$F29=5,"普通",HealthReport!$F29=0,"重要")} -> PASS
B30: 4 | C30: 主机系统分析 | D30: 文件系统使用率 | F30: 5 | G30: {=_xlfn.IFS(HealthReport!$F30>=10,"PASS",HealthReport!$F30=8,"轻微",HealthReport!$F30=5,"普通",HealthReport!$F30=0,"重要")} -> 普通 | H30: bbb | L30: =HYPERLINK("#OS!B5","Detail") -> Detail
B31: 5 | C31: 主机系统分析 | D31: 索引资源节点使用率 | F31: 10 | G31: {=_xlfn.IFS(HealthReport!$F31>=10,"PASS",HealthReport!$F31=8,"轻微",HealthReport!$F31=5,"普通",HealthReport!$F31=0,"重要")} -> PASS | L31: =HYPERLINK("#OS!A1","Detail") -> Detail
B32: 6 | C32: 主机系统分析 | D32: 主机透明大页检查 | F32: 10 | G32: {=_xlfn.IFS(HealthReport!$F32>=10,"PASS",HealthReport!$F32=8,"轻微",HealthReport!$F32=5,"普通",HealthReport!$F32=0,"重要")} -> PASS | L32: =HYPERLINK("#OS!A1","Detail") -> Detail
B33: 7 | C33: 数据库实例分析 | D33: 内核参数 | F33: 8 | G33: {=_xlfn.IFS(HealthReport!$F33>=10,"PASS",HealthReport!$F33=8,"轻微",HealthReport!$F33=5,"普通",HealthReport!$F33=0,"重要")} -> 轻微 | L33: =HYPERLINK("#OS!A1","Detail") -> Detail
B34: 8 | C34: 数据库实例分析 | D34: 资源限制 | F34: 5 | G34: {=_xlfn.IFS(HealthReport!$F34>=10,"PASS",HealthReport!$F34=8,"轻微",HealthReport!$F34=5,"普通",HealthReport!$F34=0,"重要")} -> 普通 | L34: =HYPERLINK("#OS!A1","Detail") -> Detail
B35: 9 | C35: 数据库实例分析 | D35: NUMA使用检查 | F35: 0 | G35: {=_xlfn.IFS(HealthReport!$F35>=10,"PASS",HealthReport!$F35=8,"轻微",HealthReport!$F35=5,"普通",HealthReport!$F35=0,"重要")} -> 重要 | L35: =HYPERLINK("#OS!A1","Detail") -> Detail
B36: 10 | C36: 数据库实例分析 | D36: 数据库状态检查 | F36: 0 | G36: {=_xlfn.IFS(HealthReport!$F36>=10,"PASS",HealthReport!$F36=8,"轻微",HealthReport!$F36=5,"普通",HealthReport!$F36=0,"重要")} -> 重要 | L36: =HYPERLINK("#OS!A1","Detail") -> Detail
B37: 11 | C37: 数据库备份检查 | D37: 表空间使用率 | F37: 0 | G37: {=_xlfn.IFS(HealthReport!$F37>=10,"PASS",HealthReport!$F37=8,"轻微",HealthReport!$F37=5,"普通",HealthReport!$F37=0,"重要")} -> 重要 | L37: =HYPERLINK("#OS!A1","Detail") -> Detail
B38: 12 | C38: 数据库安全检查 | F38: 0 | G38: {=_xlfn.IFS(HealthReport!$F38>=10,"PASS",HealthReport!$F38=8,"轻微",HealthReport!$F38=5,"普通",HealthReport!$F38=0,"重要")} -> 重要 | L38: =HYPERLINK("#OS!A1","Detail") -> Detail
B39: 13 | C39: 其他项检查 | F39: 0 | G39: {=_xlfn.IFS(HealthReport!$F39>=10,"PASS",HealthReport!$F39=8,"轻微",HealthReport!$F39=5,"普通",HealthReport!$F39=0,"重要")} -> 重要 | L39: =HYPERLINK("#OS!A1","Detail") -> Detail

Sheet OS
A1: 主机名 | B1: HOSTNAME | C1: NODE1.HOSTNAME | D1: NODE1.HOSTNAME
A2: IP地址 | B2: IPADDR
A3: 操作系统 | B3: OS
A4: 系统版本 | B4: RELVER | C4: 10.224.209.155 | D4: 10.224.209.156
A5: CPU | B5: CORES
A6: CPU数量 | B6: CPUCOUNT
A7: CPU主频 | B7: CPUMHZ | E7: =HYPERLINK("#HealthReport!B30","Retrun") -> Retrun
A8: 内存 | B8: MEMTOTAL
A9: 交换分区 | B9: SWAPTOTAL
A10: 内核参数 | B10: OSPARAMETER
A11: ULIMIT限制 | B11: ULIMIT
A12: 系统日志 | B12: OSLOG
A13: 文件系统使用率 | B13: FILESYSTEM
A14: 索引资源使用率 | B14: INODEUSAGE
A15: CPU使用 | B15: CPUSTAT
A16: 内存使用 | B16: MEMSTAT
A17: 磁盘IO负载 | B17: IOSTAT
A18: 透明大页 | B18: THPSTAT
A19: 系统大页 | B19: HUGPAGE
... A27: RPM包-OPENVMTOOLS | B27: RPM_OPENVMTOOLS

Sheet DB
A1: 数据库名称 | B1: DBNAME | C1: APC2DB
A2: 数据库架构 | B2: DBMAA
A3: 数据库版本 | B3: DBVER
A4: 数据库状态 | B4: DBSTATUS
A5: 字符集 | B5: DBLANG
A6: 是否开启归档 | B6: LOGMODE
A7: 是否开启闪回 | B7: FLASHBACK
A8: 数据库总大小GB | B8: DBTOTALSIZE
A9: 数据文件数量 | B9: DBFILECOUNT
A10: 表数量 | B10: DBTBLCOUNT
A11: 主备库角色 | B11: DBROLE
A12: 表空间使用率 | B12: DBTBSUSAGE
A13: 数据文件状态检查 | B13: DBDATAFILE | C13: FILE_NAME STATUS CUR_GB AUT MAX_GB -------------------------------------------------------------------------------- ---------- ---------- --- ---------- +DATA/RACDB/DATAFILE/sysaux.258.1205668119 AVAILABLE 1.21 YES 32 +DATA/RACDB/DATAFILE/system.257.1205668083 AVAILABLE 1.08 YES 32 +DATA/RACDB/DATAFILE/undotbs1.259.1205668145 AVAILABLE 1 YES 32 +DATA/RACDB/DATAFILE/undotbs2.270.1205669557 AVAILABLE .05 YES 32 +DATA/RACDB/DATAFILE/users.260.1205668147 AVAILABLE 0 YES 32 5 rows selected.
A14: 数据文件大小检查 | B14: DATAFILE_SIZE | C14: FILE_NAME STATUS CUR_GB AUT MAX_GB ---------------------------------------------------------------------- ---------- -------------------- --- -------------------- /apc2db_db/db_11g/APF_TBS01.dbf AVAILABLE .550 YES 6.060 /apc2db_db/db_11g/APF_TBS_BK01.dbf AVAILABLE .200 YES 6.060 /apc2db_db/db_11g/AUDIT_TS_01.dbf AVAILABLE 1.660 YES 6.350 /apc2db_db/db_11g/CIM_LOB_DTS_01.dbf AVAILABLE 3.910 YES 6.060 /apc2db_db/db_11g/CIM_LOB_DTS_02.dbf AVAILABLE 3.220 YES 6.060 /apc2db_db/db_11g/MCS_8M_DTS_01.dbf AVAILABLE .200 YES 6.060 /apc2db_db/db_11g/MCS_8M_DTS_02.dbf AVAILABLE .200 YES 6.060 /apc2db_db/db_11g/MCS_8M_DTS_03.dbf AVAILABLE .200 YES 6.060 /apc2db_db/db_11g/MCS_8M_DTS_04.dbf AVAILABLE .200 YES 6.060 /apc2db_db/db_11g/N_APCDEV01.dbf AVAILABLE 6.060 YES 6.060 /apc2db_db/db_11g/N_APCDEV02.dbf AVAILABLE 6.060 YES 6.060 /apc2db_db/db_11g/N_APCDEV03.dbf AVAILABLE 6.060 YES 6.060 /apc2db_db/db_11g/N_APCDEV04.dbf AVAILABLE 6.060 YES 6.060 /apc2db_db/db_11g/N_APCDEV05.dbf AVAILABLE 6.060 YES 6.060 /apc2db_db/db_11g/N_APCDEV06.dbf AVAILABLE 6.060 YES 6.060 /apc2db_db/db_11g/N_APCDEV07.dbf AVAILABLE 6.060 YES 6.060 /apc2db_db/db_11g/N_APCDEV08.dbf AVAILABLE 5.810 YES 5.910 /apc2db_db/db_11g/N_APCDEV09.dbf AVAILABLE 2.640 YES 6.060 /apc2db_db/db_11g/N_CIM_100M_DTS_01.dbf AVAILABLE 6.060 YES 6.060 /apc2db_db/db_11g/N_CIM_100M_DTS_02.dbf AVAILABLE 6.060 YES 6.060 /apc2db_db/db_11g/N_CIM_100M_DTS_03.dbf AVAILABLE 6.060 YES 6.060 /apc2db_db/db_11g/N_CIM_100M_DTS_04.dbf AVAILABLE 6.060 YES 6.060 /apc2db_db/db_11g/N_CIM_100M_DTS_05.dbf AVAILABLE 6.060 YES 6.060 /apc2db_db/db_11g/N_CIM_100M_DTS_06.dbf AVAILABLE 6.060 YES 6.060 /apc2db_db/db_11g/N_CIM_100M_DTS_07.dbf AVAILABLE 6.060 YES 6.060 /apc2db_db/db_11g/N_CIM_100M_DTS_08.dbf AVAILABLE 6.060 YES 6.060 /apc2db_db/db_11g/N_CIM_100M_DTS_09.dbf AVAILABLE 6.060 YES 6.060 /apc2db_db/db_11g/N_CIM_100M_DTS_10.dbf AVAILABLE 6.060 YES 6.060 /apc2db_db/db_11g/N_CIM_100M_DTS_11.dbf AVAILABLE 6.060 YES 6.060 /apc2db_db/db_11g/N_CIM_100M_DTS_12.dbf AVAILABLE 6.060 YES 6.060 /apc2db_db/db_11g/N_CIM_100M_DTS_13.dbf AVAILABLE 6.060 YES 6.060 /apc2db_db/db_11g/N_CIM_100M_DTS_14.dbf AVAILABLE 6.060 YES 6.060 /apc2db_db/db_11g/N_CIM_100M_DTS_15.dbf AVAILABLE 6.060 YES 6.060 /apc2db_db/db_11g/N_CIM_100M_DTS_16.dbf AVAILABLE 6.060 YES 6.060 /apc2db_db/db_11g/N_CIM_100M_DTS_17.dbf AVAILABLE 6.060 YES 6.060 /apc2db_db/db_11g/N_CIM_100M_DTS_18.dbf AVAILABLE 6.060 YES 6.060 /apc2db_db/db_11g/N_CIM_100M_DTS_19.dbf AVAILABLE 6.060 YES 6.060 /apc2db_db/db_11g/N_CIM_100M_DTS_20.dbf AVAILABLE 6.060 YES 6.060 /apc2db_db/db_11g/N_CIM_100M_DTS_21.dbf AVAILABLE 6.060 YES 6.060 /apc2db_db/db_11g/N_CIM_100M_DTS_22.dbf AVAILABLE 6.060 YES 6.060 /apc2db_db/db_11g/N_CIM_100M_DTS_23.dbf AVAILABLE 6.060 YES 6.060 /apc2db_db/db_11g/N_CIM_100M_DTS_24.dbf AVAILABLE 6.060 YES 6.060 /apc2db_db/db_11g/N_CIM_100M_DTS_25.dbf AVAILABLE 6.060 YES 6.060 /apc2db_db/db_11g/N_CIM_100M_DTS_26.dbf AVAILABLE 6.060 YES 6.060 /apc2db_db/db_11g/N_CIM_100M_DTS_27.dbf AVAILABLE 6.060 YES 6.060 /apc2db_db/db_11g/N_CIM_100M_DTS_28.dbf AVAILABLE 6.060 YES 6.060 /apc2db_db/db_11g/N_CIM_100M_DTS_29.dbf AVAILABLE 6.060 YES 6.060 /apc2db_db/db_11g/N_CIM_100M_DTS_30.dbf AVAILABLE 6.060 YES 6.060 /apc2db_db/db_11g/N_CIM_100M_DTS_31.dbf AVAILABLE 6.060 YES 6.060 /apc2db_db/db_11g/N_CIM_100M_DTS_32.dbf AVAILABLE 6.060 YES 6.060 /apc2db_db/db_11g/N_CIM_100M_DTS_33.dbf AVAILABLE 6.060 YES 6.060 /apc2db_db/db_11g/N_CIM_100M_DTS_34.dbf AVAILABLE 6.060 YES 6.060 /apc2db_db/db_11g/N_CIM_100M_DTS_35.dbf AVAILABLE 6.060 YES 6.060 /apc2db_db/db_11g/N_CIM_100M_DTS_36.dbf AVAILABLE 6.060 YES 6.060 /apc2db_db/db_11g/N_CIM_100M_DTS_37.dbf AVAILABLE 6.060 YES 6.060 /apc2db_db/db_11g/N_CIM_100M_DTS_38.dbf AVAILABLE 6.060 YES 6.060 /apc2db_db/db_11g/N_CIM_100M_DTS_39.dbf AVAILABLE 6.060 YES 6.060 /apc2db_db/db_11g/N_CIM_100M_DTS_40.dbf AVAILABLE 4.590 YES 6.060 /apc2db_db/db_11g/N_CIM_100M_DTS_41.dbf AVAILABLE 4.590 YES 6.060 /apc2db_db/db_11g/N_CIM_100M_DTS_42.dbf AVAILABLE 2.930 YES 6.060 /apc2db_db/db_11g/N_CIM_100M_DTS_43.dbf AVAILABLE 2.930 YES 6.060 /apc2db_db/db_11g/N_CIM_100M_DTS_44.dbf AVAILABLE 1.370 YES 6.060 /apc2db_db/db_11g/N_CIM_100M_DTS_45.dbf AVAILABLE 1.370 YES 6.060 /apc2db_db/db_11g/N_CIM_100M_ITS_01.dbf AVAILABLE 2.540 YES 6.060 /apc2db_db/db_11g/N_CIM_100M_ITS_02.dbf AVAILABLE .780 YES 6.060 /apc2db_db/db_11g/N_CIM_128K_DTS_01.dbf AVAILABLE 5.760 YES 6.060 /apc2db_db/db_11g/N_CIM_128K_DTS_02.dbf AVAILABLE 5.370 YES 6.060 /apc2db_db/db_11g/N_CIM_128K_ITS_01.dbf AVAILABLE 3.810 YES 6.060 /apc2db_db/db_11g/N_CIM_128K_ITS_02.dbf AVAILABLE 3.520 YES 6.060 /apc2db_db/db_11g/N_CIM_1M_DTS_01.dbf AVAILABLE 6.060 YES 6.060 /apc2db_db/db_11g/N_CIM_1M_DTS_02.dbf AVAILABLE 6.060 YES 6.060 /apc2db_db/db_11g/N_CIM_1M_DTS_03.dbf AVAILABLE 5.910 YES 5.910 /apc2db_db/db_11g/N_CIM_1M_DTS_04.dbf AVAILABLE 6.060 YES 6.060 /apc2db_db/db_11g/N_CIM_1M_DTS_05.dbf AVAILABLE 6.060 YES 6.060 /apc2db_db/db_11g/N_CIM_1M_DTS_06.dbf AVAILABLE 4.490 YES 6.060 /apc2db_db/db_11g/N_CIM_1M_DTS_07.dbf AVAILABLE .590 YES 6.060 /apc2db_db/db_11g/N_CIM_1M_ITS_01.dbf AVAILABLE 6.060 YES 6.060 /apc2db_db/db_11g/N_CIM_1M_ITS_02.dbf AVAILABLE 6.060 YES 6.060 /apc2db_db/db_11g/N_CIM_1M_ITS_03.dbf AVAILABLE 6.060 YES 6.060 /apc2db_db/db_11g/N_CIM_1M_ITS_04.dbf AVAILABLE 6.060 YES 6.060 /apc2db_db/db_11g/N_CIM_1M_ITS_05.dbf AVAILABLE 6.060 YES 6.060 /apc2db_db/db_11g/N_CIM_1M_ITS_06.dbf AVAILABLE 6.060 YES 6.060 /apc2db_db/db_11g/N_CIM_1M_ITS_07.dbf AVAILABLE 6.060 YES 6.060 /apc2db_db/db_11g/N_CIM_1M_ITS_08.dbf AVAILABLE 6.060 YES 6.060 /apc2db_db/db_11g/N_CIM_1M_ITS_09.dbf AVAILABLE 6.060 YES 6.060 /apc2db_db/db_11g/N_CIM_1M_ITS_10.dbf AVAILABLE 6.060 YES 6.060 /apc2db_db/db_11g/N_CIM_1M_ITS_11.dbf AVAILABLE 6.060 YES 6.060 /apc2db_db/db_11g/N_CIM_1M_ITS_12.dbf AVAILABLE 6.060 YES 6.060 /apc2db_db/db_11g/N_CIM_1M_ITS_13.dbf AVAILABLE 6.060 YES 6.060 /apc2db_db/db_11g/N_CIM_1M_ITS_14.dbf AVAILABLE 6.060 YES 6.060 /apc2db_db/db_11g/N_CIM_1M_ITS_15.dbf AVAILABLE 6.060 YES 6.060 /apc2db_db/db_11g/N_CIM_1M_ITS_16.dbf AVAILABLE 6.060 YES 6.060 /apc2db_db/db_11g/N_CIM_1M_ITS_17.dbf AVAILABLE 6.060 YES 6.060 /apc2db_db/db_11g/N_CIM_1M_ITS_18.dbf AVAILABLE 6.060 YES 6.060 /apc2db_db/db_11g/N_CIM_1M_ITS_19.dbf AVAILABLE 6.060 YES 6.060 /apc2db_db/db_11g/N_CIM_1M_ITS_20.dbf AVAILABLE 6.060 YES 6.060 /apc2db_db/db_11g/N_CIM_1M_ITS_21.dbf AVAILABLE 6.060 YES 6.060 /apc2db_db/db_11g/N_CIM_1M_ITS_22.dbf AVAILABLE 6.060 YES 6.060 /apc2db_db/db_11g/N_CIM_1M_ITS_23.dbf AVAILABLE 6.060 YES 6.060 /apc2db_db/db_11g/N_CIM_1M_ITS_24.dbf AVAILABLE 6.060 YES 6.060 /apc2db_db/db_11g/N_CIM_1M_ITS_25.dbf AVAILABLE 6.060 YES 6.060 /apc2db_db/db_11g/N_CIM_1M_ITS_26.dbf AVAILABLE 6.060 YES 6.060 /apc2db_db/db_11g/N_CIM_1M_ITS_27.dbf AVAILABLE 6.060 YES 6.060 /apc2db_db/db_11g/N_CIM_1M_ITS_28.dbf AVAILABLE 6.060 YES 6.060 /apc2db_db/db_11g/N_CIM_1M_ITS_29.dbf AVAILABLE 6.060 YES 6.060 /apc2db_db/db_11g/N_CIM_1M_ITS_30.dbf AVAILABLE 6.060 YES 6.060 /apc2db_db/db_11g/N_CIM_1M_ITS_31.dbf AVAILABLE 6.060 YES 6.060 /apc2db_db/db_11g/N_CIM_1M_ITS_32.dbf AVAILABLE 6.060 YES 6.060 /apc2db_db/db_11g/N_CIM_1M_ITS_33.dbf AVAILABLE 6.060 YES 6.060 /apc2db_db/db_11g/N_CIM_1M_ITS_34.dbf AVAILABLE 6.060 YES 6.060 /apc2db_db/db_11g/N_CIM_1M_ITS_35.dbf AVAILABLE 6.060 YES 6.060 /apc2db_db/db_11g/N_CIM_1M_ITS_36.dbf AVAILABLE 6.060 YES 6.060 /apc2db_db/db_11g/N_CIM_1M_ITS_37.dbf AVAILABLE 6.060 YES 6.060 /apc2db_db/db_11g/N_CIM_1M_ITS_38.dbf AVAILABLE 6.060 YES 6.060 /apc2db_db/db_11g/N_CIM_1M_ITS_39.dbf AVAILABLE 6.060 YES 6.060 /apc2db_db/db_11g/N_CIM_1M_ITS_40.dbf AVAILABLE 5.910 YES 5.910 /apc2db_db/db_11g/N_CIM_1M_ITS_41.dbf AVAILABLE 5.910 YES 5.910 /apc2db_db/db_11g/N_CIM_1M_ITS_42.dbf AVAILABLE 5.910 YES 5.910 /apc2db_db/db_11g/N_CIM_1M_ITS_43.dbf AVAILABLE 6.060 YES 6.060 /apc2db_db/db_11g/N_CIM_1M_ITS_44.dbf AVAILABLE 6.060 YES 6.060 /apc2db_db/db_11g/N_CIM_1M_ITS_45.dbf AVAILABLE 5.910 YES 5.910 /apc2db_db/db_11g/N_CIM_1M_ITS_46.dbf AVAILABLE 5.910 YES 5.910 /apc2db_db/db_11g/N_CIM_1M_ITS_47.dbf AVAILABLE 6.060 YES 6.060 /apc2db_db/db_11g/N_CIM_1M_ITS_48.dbf AVAILABLE 6.060 YES 6.060 /apc2db_db/db_11g/N_CIM_1M_ITS_49.dbf AVAILABLE 6.060 YES 6.060 /apc2db_db/db_11g/N_CIM_1M_ITS_50.dbf AVAILABLE 6.060 YES 6.060 /apc2db_db/db_11g/N_CIM_1M_ITS_51.dbf AVAILABLE 5.910 YES 5.910 /apc2db_db/db_11g/N_CIM_1M_ITS_52.dbf AVAILABLE 5.910 YES 5.910 /apc2db_db/db_11g/N_CIM_1M_ITS_53.dbf AVAILABLE 5.910 YES 5.910 /apc2db_db/db_11g/N_CIM_1M_ITS_54.dbf AVAILABLE 5.910 YES 5.910 /apc2db_db/db_11g/N_CIM_1M_ITS_55.dbf AVAILABLE 5.910 YES 5.910 /apc2db_db/db_11g/N_CIM_1M_ITS_56.dbf AVAILABLE 5.910 YES 5.910 /apc2db_db/db_11g/N_CIM_1M_ITS_57.dbf AVAILABLE 5.420 YES 5.910 /apc2db_db/db_11g/N_CIM_1M_ITS_58.dbf AVAILABLE 5.420 YES 5.910 /apc2db_db/db_11g/N_CIM_1M_ITS_59.dbf AVAILABLE 3.570 YES 5.910 /apc2db_db/db_11g/N_CIM_1M_ITS_60.dbf AVAILABLE 3.470 YES 5.910 /apc2db_db/db_11g/N_CIM_1M_ITS_61.dbf AVAILABLE 1.320 YES 5.910 /apc2db_db/db_11g/N_CIM_1M_ITS_62.dbf AVAILABLE 1.320 YES 5.910 /apc2db_db/db_11g/N_CIM_1M_ITS_63.dbf AVAILABLE 1.470 YES 6.060 /apc2db_db/db_11g/N_CIM_1M_ITS_64.dbf AVAILABLE 1.470 YES 6.060 /apc2db_db/db_11g/N_CIM_1M_ITS_65.dbf AVAILABLE 1.470 YES 6.060 /apc2db_db/db_11g/N_CIM_1M_ITS_66.dbf AVAILABLE 1.470 YES 6.060 /apc2db_db/db_11g/N_CIM_1M_ITS_67.dbf AVAILABLE 1.470 YES 6.060 /apc2db_db/db_11g/N_CIM_1M_ITS_68.dbf AVAILABLE 1.470 YES 6.060 /apc2db_db/db_11g/N_CIM_1M_ITS_69.dbf AVAILABLE 1.370 YES 6.060 /apc2db_db/db_11g/N_CIM_20M_ITS_01.dbf AVAILABLE 6.060 YES 6.060 /apc2db_db/db_11g/N_CIM_20M_ITS_02.dbf AVAILABLE 6.060 YES 6.060 /apc2db_db/db_11g/N_CIM_20M_ITS_03.dbf AVAILABLE 6.060 YES 6.060 /apc2db_db/db_11g/N_CIM_20M_ITS_04.dbf AVAILABLE 6.060 YES 6.060 /apc2db_db/db_11g/N_CIM_20M_ITS_05.dbf AVAILABLE 6.060 YES 6.060 /apc2db_db/db_11g/N_CIM_20M_ITS_06.dbf AVAILABLE 6.060 YES 6.060 /apc2db_db/db_11g/N_CIM_20M_ITS_07.dbf AVAILABLE 6.060 YES 6.060 /apc2db_db/db_11g/N_CIM_20M_ITS_08.dbf AVAILABLE 6.060 YES 6.060 /apc2db_db/db_11g/N_CIM_20M_ITS_09.dbf AVAILABLE 6.060 YES 6.060 /apc2db_db/db_11g/N_CIM_20M_ITS_10.dbf AVAILABLE 6.060 YES 6.060 /apc2db_db/db_11g/N_CIM_20M_ITS_11.dbf AVAILABLE 6.060 YES 6.060 /apc2db_db/db_11g/N_CIM_20M_ITS_12.dbf AVAILABLE 6.060 YES 6.060 /apc2db_db/db_11g/N_CIM_20M_ITS_13.dbf AVAILABLE 6.060 YES 6.060 /apc2db_db/db_11g/N_CIM_20M_ITS_14.dbf AVAILABLE 6.060 YES 6.060 /apc2db_db/db_11g/N_CIM_20M_ITS_15.dbf AVAILABLE 6.060 YES 6.060 /apc2db_db/db_11g/N_CIM_20M_ITS_16.dbf AVAILABLE 6.060 YES 6.060 /apc2db_db/db_11g/N_CIM_20M_ITS_17.dbf AVAILABLE 6.060 YES 6.060 /apc2db_db/db_11g/N_CIM_20M_ITS_18.dbf AVAILABLE 6.060 YES 6.060 /apc2db_db/db_11g/N_CIM_20M_ITS_19.dbf AVAILABLE 6.060 YES 6.060 /apc2db_db/db_11g/N_CIM_20M_ITS_20.dbf AVAILABLE 6.060 YES 6.060 /apc2db_db/db_11g/N_CIM_20M_ITS_21.dbf AVAILABLE 6.060 YES 6.060 /apc2db_db/db_11g/N_CIM_20M_ITS_22.dbf AVAILABLE 6.060 YES 6.060 /apc2db_db/db_11g/N_CIM_20M_ITS_23.dbf AVAILABLE 6.060 YES 6.060 /apc2db_db/db_11g/N_CIM_20M_ITS_24.dbf AVAILABLE 6.060 YES 6.060 /apc2db_db/db_11g/N_CIM_20M_ITS_25.dbf AVAILABLE 6.060 YES 6.060 /apc2db_db/db_11g/N_CIM_20M_ITS_26.dbf AVAILABLE 6.060 YES 6.060 /apc2db_db/db_11g/N_CIM_20M_ITS_27.dbf AVAILABLE 6.060 YES 6.060 /apc2db_db/db_11g/N_CIM_20M_ITS_28.dbf AVAILABLE 6.060 YES 6.060 /apc2db_db/db_11g/N_CIM_20M_ITS_29.dbf AVAILABLE 6.060 YES 6.060 /apc2db_db/db_11g/N_CIM_20M_ITS_30.dbf AVAILABLE 6.060 YES 6.060 /apc2db_db/db_11g/N_CIM_20M_ITS_31.dbf AVAILABLE 6.060 YES 6.060 /apc2db_db/db_11g/N_CIM_20M_ITS_32.dbf AVAILABLE 6.060 YES 6.060 /apc2db_db/db_11g/N_CIM_20M_ITS_33.dbf AVAILABLE 6.060 YES 6.060 /apc2db_db/db_11g/N_CIM_20M_ITS_34.dbf AVAILABLE 6.060 YES 6.060 /apc2db_db/db_11g/N_CIM_20M_ITS_35.dbf AVAILABLE 6.060 YES 6.060 /apc2db_db/db_11g/N_CIM_20M_ITS_36.dbf AVAILABLE 6.060 YES 6.060 /apc2db_db/db_11g/N_CIM_20M_ITS_37.dbf AVAILABLE 6.060 YES 6.060 /apc2db_db/db_11g/N_CIM_20M_ITS_38.dbf AVAILABLE 6.060 YES 6.060 /apc2db_db/db_11g/N_CIM_20M_ITS_39.dbf AVAILABLE 6.060 YES 6.060 /apc2db_db/db_11g/N_CIM_20M_ITS_40.dbf AVAILABLE 5.910 YES 5.910 /apc2db_db/db_11g/N_CIM_20M_ITS_41.dbf AVAILABLE 5.910 YES 5.910 /apc2db_db/db_11g/N_CIM_20M_ITS_42.dbf AVAILABLE 5.910 YES 5.910 /apc2db_db/db_11g/N_CIM_20M_ITS_43.dbf AVAILABLE 5.910 YES 5.910 /apc2db_db/db_11g/N_CIM_20M_ITS_44.dbf AVAILABLE 5.420 YES 5.910 /apc2db_db/db_11g/N_CIM_20M_ITS_45.dbf AVAILABLE 5.420 YES 5.910 /apc2db_db/db_11g/N_CIM_20M_ITS_46.dbf AVAILABLE 3.610 YES 6.060 /apc2db_db/db_11g/N_CIM_20M_ITS_47.dbf AVAILABLE 3.610 YES 6.060 /apc2db_db/db_11g/N_CIM_20M_ITS_48.dbf AVAILABLE 3.610 YES 6.060 /apc2db_db/db_11g/N_CIM_20M_ITS_49.dbf AVAILABLE .200 YES 5.860 /apc2db_db/db_11g/N_CIM_20M_ITS_50.dbf AVAILABLE .200 YES 5.860 /apc2db_db/db_11g/N_CIM_20M_ITS_51.dbf AVAILABLE .200 YES 5.860 /apc2db_db/db_11g/N_CIM_20M_ITS_52.dbf AVAILABLE .200 YES 5.860 /apc2db_db/db_11g/N_CIM_20M_ITS_53.dbf AVAILABLE .200 YES 5.860 /apc2db_db/db_11g/N_CIM_20M_ITS_54.dbf AVAILABLE .200 YES 5.860 /apc2db_db/db_11g/N_CIM_20M_ITS_55.dbf AVAILABLE .200 YES 5.860 /apc2db_db/db_11g/N_CIM_20M_ITS_56.dbf AVAILABLE .200 YES 5.860 /apc2db_db/db_11g/N_CIM_20M_ITS_57.dbf AVAILABLE .200 YES 5.860 /apc2db_db/db_11g/N_CIM_20M_ITS_58.dbf AVAILABLE .200 YES 5.860 /apc2db_db/db_11g/N_CIM_20M_ITS_59.dbf AVAILABLE .200 YES 5.860 /apc2db_db/db_11g/N_CIM_8M_DTS_01.dbf AVAILABLE 6.060 YES 6.060 /apc2db_db/db_11g/N_CIM_8M_DTS_02.dbf AVAILABLE 6.060 YES 6.060 /apc2db_db/db_11g/N_CIM_8M_DTS_03.dbf AVAILABLE 6.060 YES 6.060 /apc2db_db/db_11g/N_CIM_8M_DTS_04.dbf AVAILABLE 6.060 YES 6.060 /apc2db_db/db_11g/N_CIM_8M_DTS_05.dbf AVAILABLE 6.060 YES 6.060 /apc2db_db/db_11g/N_CIM_8M_DTS_06.dbf AVAILABLE 6.060 YES 6.060 /apc2db_db/db_11g/N_CIM_8M_DTS_07.dbf AVAILABLE 6.060 YES 6.060 /apc2db_db/db_11g/N_CIM_8M_DTS_08.dbf AVAILABLE 6.060 YES 6.060 /apc2db_db/db_11g/N_CIM_8M_DTS_09.dbf AVAILABLE 6.060 YES 6.060 /apc2db_db/db_11g/N_CIM_8M_DTS_10.dbf AVAILABLE 6.060 YES 6.060 /apc2db_db/db_11g/N_CIM_8M_DTS_11.dbf AVAILABLE 6.060 YES 6.060 /apc2db_db/db_11g/N_CIM_8M_DTS_12.dbf AVAILABLE 6.060 YES 6.060 /apc2db_db/db_11g/N_CIM_8M_DTS_13.dbf AVAILABLE 6.060 YES 6.060 /apc2db_db/db_11g/N_CIM_8M_DTS_14.dbf AVAILABLE 6.060 YES 6.060 /apc2db_db/db_11g/N_CIM_8M_DTS_15.dbf AVAILABLE 6.060 YES 6.060 /apc2db_db/db_11g/N_CIM_8M_DTS_16.dbf AVAILABLE 6.060 YES 6.060 /apc2db_db/db_11g/N_CIM_8M_DTS_17.dbf AVAILABLE 6.060 YES 6.060 /apc2db_db/db_11g/N_CIM_8M_DTS_18.dbf AVAILABLE 6.060 YES 6.060 /apc2db_db/db_11g/N_CIM_8M_DTS_19.dbf AVAILABLE 6.060 YES 6.060 /apc2db_db/db_11g/N_CIM_8M_DTS_20.dbf AVAILABLE 6.060 YES 6.060 /apc2db_db/db_11g/N_CIM_8M_DTS_21.dbf AVAILABLE 5.910 YES 5.910 /apc2db_db/db_11g/N_CIM_8M_DTS_22.dbf AVAILABLE 5.910 YES 5.910 /apc2db_db/db_11g/N_CIM_8M_DTS_23.dbf AVAILABLE 5.910 YES 5.910 /apc2db_db/db_11g/N_CIM_8M_DTS_24.dbf AVAILABLE 5.910 YES 5.910 /apc2db_db/db_11g/N_CIM_8M_DTS_25.dbf AVAILABLE 5.910 YES 5.910 /apc2db_db/db_11g/N_CIM_8M_DTS_26.dbf AVAILABLE 5.910 YES 5.910 /apc2db_db/db_11g/N_CIM_8M_DTS_27.dbf AVAILABLE 5.910 YES 5.910 /apc2db_db/db_11g/N_CIM_8M_DTS_28.dbf AVAILABLE 5.910 YES 5.910 /apc2db_db/db_11g/N_CIM_8M_DTS_29.dbf AVAILABLE 6.060 YES 6.060 /apc2db_db/db_11g/N_CIM_8M_DTS_30.dbf AVAILABLE 6.060 YES 6.060 /apc2db_db/db_11g/N_CIM_8M_DTS_31.dbf AVAILABLE 6.060 YES 6.060 /apc2db_db/db_11g/N_CIM_8M_DTS_32.dbf AVAILABLE 6.060 YES 6.060 /apc2db_db/db_11g/N_CIM_8M_DTS_33.dbf AVAILABLE 6.060 YES 6.060 /apc2db_db/db_11g/N_CIM_8M_DTS_34.dbf AVAILABLE 6.060 YES 6.060 /apc2db_db/db_11g/N_CIM_8M_DTS_35.dbf AVAILABLE 6.060 YES 6.060 /apc2db_db/db_11g/N_CIM_8M_DTS_36.dbf AVAILABLE 6.060 YES 6.060 /apc2db_db/db_11g/N_CIM_8M_DTS_37.dbf AVAILABLE 5.910 YES 5.910 /apc2db_db/db_11g/N_CIM_8M_DTS_38.dbf AVAILABLE 5.910 YES 5.910 /apc2db_db/db_11g/N_CIM_8M_DTS_39.dbf AVAILABLE 5.910 YES 5.910 /apc2db_db/db_11g/N_CIM_8M_DTS_40.dbf AVAILABLE 5.910 YES 5.910 /apc2db_db/db_11g/N_CIM_8M_DTS_41.dbf AVAILABLE 5.910 YES 5.910 /apc2db_db/db_11g/N_CIM_8M_DTS_42.dbf AVAILABLE 5.910 YES 5.910 /apc2db_db/db_11g/N_CIM_8M_DTS_43.dbf AVAILABLE 6.060 YES 6.060 /apc2db_db/db_11g/N_CIM_8M_DTS_44.dbf AVAILABLE 6.060 YES 6.060 /apc2db_db/db_11g/N_CIM_8M_DTS_45.dbf AVAILABLE 6.060 YES 6.060 /apc2db_db/db_11g/N_CIM_8M_DTS_46.dbf AVAILABLE 5.910 YES 5.910 /apc2db_db/db_11g/N_CIM_8M_DTS_47.dbf AVAILABLE 5.910 YES 5.910 /apc2db_db/db_11g/N_CIM_8M_DTS_48.dbf AVAILABLE 5.960 YES 5.960 /apc2db_db/db_11g/N_CIM_8M_DTS_49.dbf AVAILABLE 5.960 YES 5.960 /apc2db_db/db_11g/N_CIM_8M_DTS_50.dbf AVAILABLE 5.960 YES 5.960
A15: REDO文件检查 | B15: DBREDOCHECK | C15: GROUP# THREAD# SEQUENCE# MB ARC STATUS -------------------- -------------------- -------------------- -------------------- --- ---------- 6.000 1.000 266.000 400.000 YES INACTIVE 7.000 1.000 267.000 400.000 YES INACTIVE 8.000 1.000 268.000 400.000 NO CURRENT 9.000 1.000 264.000 400.000 YES INACTIVE 10.000 1.000 265.000 400.000 YES INACTIVE
A16: TEMP文件大小 | B16: TMPFILE_SIZE
A17: 控制文件冗余检查 | B17: DBCONTROLFILE | C17: /apc2db_db/CTL_11g/control01.ctl
A18: 用户状态 | B18: USER_INFO
A19: 用户大小 | B19: OWNER_SIZE | C19: OWNER USER_SIZE_GB ------------------------------ ------------ APCDEV 48.57 APPQOSSYS .00 AUDSYS .00 CIMMGR 1309.13 DBSFWUSER .00 DBSNMP .00 EAPDEV .86 F1MCSAPP .01 F2ISSUETAG 7.08 GSMADMIN_INTERNAL .01 MCSAPP .06 MCSMGR .23 ORAAUD .15 OUTLN .00 PERFSTAT9I .00 RLTDEV 2.69 RTDELT .03 RTDUSER .51 SYS 5.89 SYSTEM .03 VCSUSER .00 WMSYS .01 WSSAPP .21 XDB .04
A20: 用户表数量 | B20: TAB_INFO
A21: 资源使用限制检查 | B21: DBRESOURCE | C21: INST_ID RESOURCE_NAME CURRENT_UTILIZATION MAX_UTILIZATION LIMIT_VALUE ------- ------------------------------ ------------------- --------------- --------------- 1 processes 2495 2499 2500 1 sessions 340 474 3776 1 ges_procs 0 0 0 1 ges_rsv_msgs 0 0 0 1 parallel_max_servers 6 6 32767
A22: 并行度>1的表 | B22: DBTABLEPARALLEL
A23: 并行度>1的索引 | B23: DBINDEXPARALLEL | C23: OWNER TABLE_NAME INDEX_NAME DEGREE STATUS ------------------------------ ------------------------------ ---------------------------------------- ---------- -------- APCDEV APC_ASML_SPEC_HIS_TABLE INX_APC_ASML_SPEC_HIS_TABLE 3 VALID APCDEV APC_ASML_SPEC_TABLE PK_APC_ASML_SPEC_TABLE 3 VALID APCDEV APC_CANON_SPEC_HIS_TABLE INX_APC_CANON_HIS_TABLE 3 VALID APCDEV APC_CANON_SPEC_TABLE PK_APC_CANON_SPEC_TABLE 3 VALID APCDEV APC_CONSTANT_TABLE PK_APC_CONSTANT_TABLE 3 VALID APCDEV APC_GUI_ACTIVE_VERSION PK_APC_GUI_ACTIVE_VERSION 3 VALID APCDEV APC_OFFSET_CANON PK_APC_OFFSET_CANON 3 VALID APCDEV APC_OFFSET_TABLE PK_APC_OFFSET_TABLE 3 VALID APCDEV APC_PROD_LAYER_INFO PK_PROD_LAYER 3 VALID APCDEV APC_SPEC_CONSTANT_TABLE INX_APC_SPEC_CONSTANT_TABLE 3 VALID APCDEV APC_USER_GROUP PK_APC_USER_GROUP 3 VALID APCDEV EQP_SSC_TABLE PK_EQP_SSC_TABLE 3 VALID APCDEV EQP_SSC_TREND_TABLE PK_EQP_SSC_TREND_TABLE 3 VALID APCDEV EXPTOOLID_OVL_TABLE PK_EQP 3 VALID APCDEV EXPTOOLID_TABLE EXPTOOLID_TABLE_NO_CONSTR 3 VALID APCDEV FOCUS_RETICLE_TABLE PK_FOCUS_RETICLE 3 VALID APCDEV FOCUS_TABLE PK_FOCUS_TABLE 3 VALID APCDEV LAYER_EDCPLAN_RELATION LAYER_EDC_UNI 3 VALID APCDEV LOGI_PROCESS_MS_REPORT PROD_LAYER 3 VALID APCDEV LOGI_PROCESS_MS_REPORT INX_SYSID 3 VALID APCDEV LOGI_PROCESS_MS_REPORT LOGILOT_UNIQUE 3 VALID APCDEV LOOK_UP_TABLE PK_LOOK_UP_TABLE 3 VALID APCDEV LOT_OVL_PIE_TABLE PK_LOT_OVL_PIE_TABLE 3 VALID APCDEV OVL_PIE_TABLE_2017BAK OVL_PIE_INDEX_1 3 VALID APCDEV OVL_PIE_TABLE_2017BAK PK_OVL_PIE_TABLE 3 VALID APCDEV OVL_PRODUCTION_DATA_CANON INX_OVL_PRODUCTION_DATA_CANON 3 VALID APCDEV PCMBX_ALL_TABLE PK_PCMBX 3 VALID APCDEV PROCESS_CONDITION_CANON INX_PROCESS_CONDITION_CANON 3 VALID APCDEV PROCESS_INIT_OVL_TABLE PK_PROCESS_INIT_OVL_TABLE 3 VALID APCDEV PROCESS_INIT_TABLE PK_PROCESS_INIT_TABLE 3 VALID APCDEV PROCESS_OVL_REPORT PK_PROCESS_OVL_REPORT 3 VALID APCDEV PROCESS_OVL_REPORT PROCESS_OVL_INDEX1 3 VALID APCDEV PROCESS_OVL_REPORT PROD_LAYER_LOTID 3 VALID APCDEV PROCESS_OVL_REPORT PROCESS_OVL_REPORT_INX1 3 VALID APCDEV PRODUCT_TABLE PK_PRODUCT_TABLE 3 VALID APCDEV PROD_OVL_LOOKUP_TABLE PK_PROD_OVL_LOOKUP_TABLE 3 VALID APCDEV REWORK_LOT_KEYIN_CANON PK_REWORK_CANON 3 VALID APCDEV REWORK_LOT_KEYIN_TABLE PK_REWORK 3 VALID APCDEV SCANNER_MONITOR_CANON PK_SCANNER_MONITOR_CANON 3 VALID APCDEV SCANNER_MONITOR_TABLE PK_SCANNER_MONITOR_TABLE 3 VALID APCDEV SCANNER_PM_TABLE PK_SCANNER_PM_TABLE 3 VALID APCDEV SCANNER_STATUS_CANON PK_SCANNER_STATUS_CANON 3 VALID APCDEV SCANNER_STATUS_TABLE PK_SCANNER_STATUS_TABLE 3 VALID CIMMGR CIM_GROUPS PK_CIM_GROUPS 3 VALID CIMMGR CIM_SYSTEMS PK_CIM_SYSTEMS 3 VALID CIMMGR CIM_SYS_ENTITIES PK_CIM_SYS_ENTITIES 3 VALID CIMMGR CIM_SYS_FUNCTIONS PK_CIM_SYS_FUNCTIONS 3 VALID CIMMGR CIM_USERS PK_CIM_USERS 3 VALID CIMMGR CIM_USER_GROUPS PK_CIM_USER_GROUPS 3 VALID CIMMGR EAP_CFG_GLOBAL_FAB PK_EAP_CFG_GLOBAL_FAB 3 VALID CIMMGR EAP_CFG_MODEL_EQP EAP_CFG_MODEL_EQP_INDEX1 3 VALID CIMMGR EAP_CFG_MODEL_EQP PK_EAP_CFG_MODEL_EQP 3 VALID CIMMGR EAP_CFG_MODEL_EQPTYPE PK_EAP_CFG_MODEL_EQPTYPE 3 VALID CIMMGR EAP_CFG_SECONDEQ_EQP PK_EAP_CFG_SECONDEQ_EQP 3 VALID CIMMGR EAP_CFG_SERVER_FAB PK_EAP_CFG_SERVER_FAB 3 VALID CIMMGR EAP_CFG_WORKSTATION PK_EAP_CFG_WORKSTATION 3 VALID CIMMGR EAP_CFG_SMIF PK_EAP_CFG_SMIF 3 VALID CIMMGR EAP_CFG_SERVER PK_EAP_CFG_SERVER 3 VALID CIMMGR RMS_DRAFT_RECIPE_SPEC PK_RMS_DRAFT_RECIPE_SPEC 3 VALID CIMMGR RMS_RECIPE_COMPARE_TYPE PK_RMS_RECIPE_COMPARE_TYPE 3 VALID CIMMGR RMS_RECIPE_FORMAT PK_RMS_RECIPE_FORMAT 3 VALID CIMMGR RMS_RECORD_LOCK PK_RMS_RECORD_LOCK 3 VALID CIMMGR RMS_RECIPE_MISMATCH_HISTORY PK_RMS_RECIPE_MISMATCH_HISTORY 3 VALID CIMMGR EMS_PARANAME_TABLE UK_PARA_INX 3 VALID CIMMGR EMS_PARANAME_TABLE PK_EMS_PARANAME_TABLE 3 VALID CIMMGR EMS_SPEC_TABLE PK_EMS_SPEC_TABLE 3 VALID CIMMGR EMS_SPEC_TABLE EMS_SPEC_INDEX1 3 VALID CIMMGR EMS_SPEC_TABLE EMS_SPEC_INDEX2 3 VALID CIMMGR EMS_SPEC_HISTORY_TABLE EMS_SPEC_HISTORY_INDEX1 3 VALID CIMMGR ELS_EQP_INFO PK_ELS_EQP_INFO 3 VALID CIMMGR WRC_USER_ATTRIBUTE PK_WRC_USER_ATTRIBUTE 3 VALID CIMMGR WRC_TANK_STATUS PK_WRC_TANK_STATUS 3 VALID CIMMGR WRC_RECIPE_TANK PK_WRC_RECIPE_TANK 3 VALID CIMMGR WRC_RECIPE_STATUS PK_WRC_RECIPE_STATUS 3 VALID CIMMGR RMS_KEYWORDS_FILTER PK_RMS_KEYWORDS_FILTER 3 VALID CIMMGR RCP_RECP_RECPGROUP PK_RCP_RECP_RECPGROUP 3 VALID CIMMGR RCP_RECP_EXCEPTION RECP_EXCEPTION 3 VALID CIMMGR RCP_RECPGROUP_LIST PK_RCP_RECPGROUP_LIST 3 VALID CIMMGR RCP_IMP_RECIPE PK_PROD_STEQ_STAGE_RECIPE 3 VALID CIMMGR RCP_IMP_INFO PK_PROD_STEPSEQ 3 VALID CIMMGR RCP_EQP_RECPGROUP CHAM_RECPGRP 3 VALID CIMMGR RCP_CHAMBER_EQPTYPE PK_RCP_CHAMBER_EQPTYPE 3 VALID CIMMGR EQP_PARMSPEC_TABLE_LOG PK_EQP_PARMSPEC_TABLE_LOG 3 VALID CIMMGR EQP_PARMSPEC_TABLE PK_EQP_PARMSPEC_TABLE 3 VALID CIMMGR EAP_MON_LOT_ATTRIBUTES PK_EAP_MON_LOT_ATTRIBUTES 3 VALID CIMMGR EAP_MON_EQP_ATTRIBUTES PK_EAP_MON_EQP_ATTRIBUTES 3 VALID CIMMGR ELS_OVL_TABLE PK_ELS_OVL_TABLE 3 VALID CIMMGR SCS_USER_ENTITY_PRIVS PK_SCS_USER_ENTITY_PRIVS 3 VALID CIMMGR SCS_USER_SYS_PRIVS PK_SCS_USER_SYS_PRIVS 3 VALID CIMMGR RMS_RECIPE_BODY PK_RMS_RECIPE_BODY 3 VALID CIMMGR RMS_RECIPE_SPEC PK_RMS_RECIPE_SPEC 3 VALID CIMMGR ELS_DYNAMIC_TABLE PK_ELS_DYNAMIC_TABLE 3 VALID CIMMGR ELS_DYNAMIC_TABLE LASTMODIFY_INDX 3 VALID CIMMGR ELS_DYNAMIC_TABLE ELS_DYNAMIC_LOTID_INDEX 3 VALID CIMMGR ELS_DUV_TABLE PK_ELS_DUV_TABLE 3 VALID CIMMGR WSS_RULE_LOG WSS_RULE_LOG_INX1 3 VALID CIMMGR WSS_RULE_LOG WSS_RULE_LOG_INX2 3 VALID CIMMGR WSS_RULE_INFO WSS_RULE_INFO_INX1 3 VALID CIMMGR WSS_RULE_DETAIL WSS_RULE_DETAIL_INX1 3 VALID CIMMGR WSS_REPLY_LOG WSS_REPLY_LOG_INX1 3 VALID CIMMGR WSS_REPLY_LOG WSS_REPLY_LOG_INX2 3 VALID CIMMGR PCC_PARA_SPEC PK_PCC_PARA_SPEC 3 VALID CIMMGR PCC_PARA_INFO PK_PCC_PARA_INFO 3 VALID CIMMGR PCC_PARA_INFO UNQ_PCC_PARA_INFO 3 VALID CIMMGR ELS_CDSEM_TABLE PK_ELS_CDSEM_TABLE 3 VALID CIMMGR ELS_ADI_TABLE PK_ELS_ADI_TABLE 3 VALID CIMMGR EAP_MON_SPEC_MAPPING PK_EAP_MON_SPEC_MAPPING 3 VALID CIMMGR EAP_MON_FLOW_SPEC PK_EAP_MON_FLOW_SPEC 3 VALID WSSAPP WSS_REPLY_LOG WSS_REPLY_LOG_INX1 3 VALID WSSAPP WSS_REPLY_LOG WSS_REPLY_LOG_INX2 3 VALID WSSAPP WSS_RULE_DETAIL WSS_RULE_DETAIL_INX1 3 VALID WSSAPP WSS_RULE_INFO WSS_RULE_INFO_INX1 3 VALID WSSAPP WSS_RULE_LOG WSS_RULE_LOG_INX1 3 VALID WSSAPP WSS_RULE_LOG WSS_RULE_LOG_INX2 3 VALID EAPDEV EQP_ETCHRATERECIPE_TABLE PK_EQP_ETCHRATERECIPE_TABLE 3 VALID EAPDEV EQP_METROLOGY_RECIPE_TABLE PK_EQP_METROLOGY_RECIPE_TABLE 3 VALID EAPDEV EQP_PROCESS_PROD_TABLE PK_EQP_PROCESS_PROD_TABLE 3 VALID EAPDEV EQP_PROCESS_RECIPE_TABLE PK_EQP_PROCESS_RECIPE_TABLE 3 VALID EAPDEV SORTER_USER_TABLE PK_SORTER_USER_TABLE 3 VALID F1MCSAPP OST_DAILY OST_DAILY_INDEX 3 VALID F1MCSAPP OST_DETAIL OST_DETAIL_INDEX 3 VALID F1MCSAPP SCARREJECTLOT_DETAIL SCARREJECTLOT_DETAIL_INDEX 3 VALID F1MCSAPP SCARTIMEOUT_INFO_DETAIL SCARTIMEOUT_INFO_DETAIL_INDEX 3 VALID F2ISSUETAG ISSUETAG_DETAIL ISSUETAG_DETAIL_INDEX1 3 VALID MCSAPP OST_DAILY OST_DAILY_INDEX 3 VALID MCSAPP OST_DETAIL OST_DETAIL_INDEX 3 VALID MCSAPP SCARREJECTLOT_DETAIL SCARREJECTLOT_DETAIL_INDEX 3 VALID MCSAPP SCARTIMEOUT_INFO_DETAIL SCARTIMEOUT_INFO_DETAIL_INDEX 3 VALID RLTDEV EQP_HISTORY_TABLE EQP_HISTORY_TABLE_INDEX1 3 VALID CIMMGR PCC_PARA_MULTISPEC PK_PCC_PARA_MULTISPEC 3 VALID APCDEV OVL_PIE_TABLE_BK OVL_PIE_INDEX22 3 VALID CIMMGR EMS_LIMIT_CONFIG_TABLE PK_EMS_LIMIT_CONFIG_TABLE 3 VALID WSSAPP WSS_RESULT_HISTORY WSS_RESULT_HISTORY_INX1 3 VALID WSSAPP WSS_RESULT_HISTORY WSS_RESULT_HISTORY_INX2 3 VALID APCDEV REWORK_LOT_KEYIN_NIKON PK_REWORK_NIKON 3 VALID APCDEV OVL_PIE_TABLE OVL_PIE_INDEX_MID_1 3 VALID APCDEV OVL_PIE_TABLE PK_OVL_PIE_TABLE_MID 3 VALID CIMMGR EMS_AMAT_CENTURA_DATA EMS_AMAT_CENTURA_D_IX2 2 N/A CIMMGR EMS_AMAT_CENTURA_OODATA PK_EMS_AMAT_CENTURA_WAFERINX 2 N/A CIMMGR EMS_AMAT_DPS_METAL_DATA EMS_DPS_METAL_D_IX2 2 N/A CIMMGR EMS_AMAT_DPS_METAL_OODATA PK_EMS_AMAT_DPS_METAL_INX 2 N/A CIMMGR EMS_AMAT_DPS_POLY_DATA EMS_AMAT_DPS_POLY_D_IX2 2 N/A CIMMGR EMS_AMAT_DPS_POLY_OODATA PK_EMS_AMAT_DPS_POLY_INX 2 N/A CIMMGR EMS_AMAT_EMAX_DATA EMS_AMAT_EMAX_D_IX2 2 N/A CIMMGR EMS_AMAT_EMAX_OODATA PK_EMS_AMAT_EMAX_WAFERINX 2 N/A CIMMGR EMS_AMAT_ENDURA_DATA EMS_AMAT_ENDURA_D_IX2 2 N/A CIMMGR EMS_AMAT_ENDURA_OODATA PK_EMS_AMAT_ENDURA_WAFERINX 2 N/A CIMMGR EMS_AMAT_MIRRA_DATA EMS_AMAT_MIRRA_D_IX2 2 N/A CIMMGR EMS_AMAT_MIRRA_OODATA PK_EMS_AMAT_MIRRA_WAFERINX 2 N/A CIMMGR EMS_AMAT_PRODUCER_DATA EMS_AMAT_PRODUCER_D_IX2 2 N/A CIMMGR EMS_AMAT_PRODUCER_OODATA PK_EMS_AMAT_PRODUCER_WAFERINX 2 N/A CIMMGR EMS_AMAT_QUANTUM_DATA EMS_AMAT_QUANTUM_D_IX2 2 N/A CIMMGR EMS_AMAT_QUANTUM_LEAP_DATA EMS_AMAT_QUANTUM_LEAP_D_IX2 2 N/A CIMMGR EMS_AMAT_QUANTUM_LEAP_OODATA PK_EMS_AMAT_QUANTUM_LEAP_INX 2 N/A CIMMGR EMS_AMAT_QUANTUM_OODATA PK_EMS_AMAT_QUANTUM_WAFERINX 2 N/A CIMMGR EMS_AMAT_RTP_DATA EMS_AMAT_RTP_D_IX2 2 N/A CIMMGR EMS_AMAT_RTP_OODATA PK_EMS_AMAT_RTP_WAFERINX 2 N/A CIMMGR EMS_AMAT_SUPERE_DATA EMS_AMAT_SUPERE_D_IX2 2 N/A CIMMGR EMS_AMAT_SUPERE_OODATA PK_EMS_AMAT_SUPERE_WAFERINX 2 N/A CIMMGR EMS_ASML_INLINE_1400_DATA EMS_ASML_INLINE_1400_D_IX2 2 N/A CIMMGR EMS_ASML_INLINE_1400_OODATA PK_EMS_ASML_INLINE_1400_INX 2 N/A CIMMGR EMS_ASML_INLINE_DATA EMS_ASML_INLINE_D_IX2 2 N/A CIMMGR EMS_ASML_INLINE_OODATA PK_EMS_ASML_INLINE_WAFERINX 2 N/A CIMMGR EMS_ASM_FURNACE_DATA EMS_ASM_FURNACE_D_IX2 2 N/A CIMMGR EMS_ASM_FURNACE_OODATA PK_EMS_ASM_FURNACE_WAFERINX 2 N/A CIMMGR EMS_AXCELIS_GEMINI_DATA EMS_AXCELIS_GEMINI_D_IX2 2 N/A CIMMGR EMS_AXCELIS_GEMINI_OODATA PK_EMS_AXCELIS_GEMINI_INX 2 N/A CIMMGR EMS_AXCELIS_GSD200E2_DATA EMS_AXCELIS_GSD200E2_D_IX2 2 N/A CIMMGR EMS_AXCELIS_GSD200E2_OODATA PK_EMS_AXCELIS_GSD200E2_INX 2 N/A CIMMGR EMS_AXCELIS_XE_DATA EMS_AXCELIS_XE_D_IX2 2 N/A CIMMGR EMS_CANON_INLINE_DATA EMS_CANON_INLINE_D_IX2 2 N/A CIMMGR EMS_CANON_INLINE_OODATA PK_EMS_CANON_INLINE_WAFERINX 2 N/A CIMMGR EMS_CETC_HJP200_DATA EMS_CETC_HJP200_D_IX2 2 N/A CIMMGR EMS_DNS_WS820_DATA EMS_DNS_WS820_D_IX2 2 N/A CIMMGR EMS_DNS_WS820_OODATA PK_EMS_DNS_WS820_WAFERINX 2 N/A CIMMGR EMS_KE_FURNACE_DATA EMS_KE_FURNACE_D_IX2 2 N/A CIMMGR EMS_KE_FURNACE_OODATA PK_EMS_KE_FURNACE_INX 2 N/A CIMMGR EMS_LAM_2300_DATA EMS_LAM_2300_D_IX2 2 N/A CIMMGR EMS_LAM_2300_OODATA PK_EMS_LAM_2300_WAFERINX 2 N/A CIMMGR EMS_LAM_9400A_DATA EMS_LAM_9400A_D_IX2 2 N/A CIMMGR EMS_LAM_9400_DATA EMS_LAM_9400_D_IX2 2 N/A CIMMGR EMS_LAM_9400_OODATA PK_EMS_LAM_9400_WAFERINX 2 N/A CIMMGR EMS_LAM_9600A_DATA EMS_LAM_9600A_D_IX2 2 N/A CIMMGR EMS_LAM_9600_DATA EMS_LAM_9600_D_IX2 2 N/A CIMMGR EMS_LAM_9600_OODATA PK_EMS_LAM_9600_WAFERINX 2 N/A CIMMGR EMS_LAM_EXCELAN_DATA EMS_LAM_EXCELAN_D_IX2 2 N/A CIMMGR EMS_LAM_EXCELAN_OODATA PK_EMS_LAM_EXCELAN_WAFERINX 2 N/A CIMMGR EMS_LMN_MARKER_DATA EMS_LMN_MARKER_D_IX2 2 N/A CIMMGR EMS_LMN_MARKER_OODATA PK_EMS_LMN_MARKER_WAFERINX 2 N/A CIMMGR EMS_MATTSON_ASPEN_DATA EMS_MATTSON_ASPEN_D_IX2 2 N/A CIMMGR EMS_MATTSON_ASPEN_OODATA PK_EMS_MATTSON_ASPEN_WAFERINX 2 N/A CIMMGR EMS_MATTSON_AWP3GEN_DATA EMS_MATTSON_AWP3GEN_D_IX2 2 N/A CIMMGR EMS_MATTSON_AWP3GEN_OODATA PK_EMS_MATTSON_AWP3GEN_INX 2 N/A CIMMGR EMS_NISSIN_2000AH_DATA EMS_NISSIN_2000AH_D_IX2 2 N/A CIMMGR EMS_NISSIN_2000AH_OODATA PK_EMS_NISSIN_2000AH_INX 2 N/A CIMMGR EMS_NISSIN_EX2300_DATA EMS_NISSIN_EX2300_D_IX2 2 N/A CIMMGR EMS_NISSIN_EX2300_OODATA PK_EMS_NISSIN_EX2300_WAFERINX 2 N/A CIMMGR EMS_NOVELLOUS_GAMMAR_DATA EMS_NOVELLOUS_GAMMAR_D_IX2 2 N/A CIMMGR EMS_NOVELLOUS_GAMMAR_OODATA PK_EMS_NOVELLOUS_GAMMAR_INX 2 N/A CIMMGR EMS_NOVELLUS_C2_DATA EMS_NOVELLUS_C2_D_IX2 2 N/A CIMMGR EMS_NOVELLUS_C2_OODATA PK_EMS_NOVELLUS_C2_WAFERINX 2 N/A CIMMGR EMS_PIOTECH_PF300T_DATA EMS_PIOTECH_PF300T_D_IX2 2 N/A CIMMGR EMS_PROZ_ASMLXT_DATA EMS_PROZ_ASMLXT_D_IX2 2 N/A CIMMGR EMS_SES_BW2000_OODATA PK_EMS_SES_BW2000_WAFERINX 2 N/A CIMMGR EMS_SES_PEAGUS_OODATA PK_EMS_SES_PEAGUS_WAFERINX 2 N/A CIMMGR EMS_SES_PEGASUS_DATA EMS_SES_PEAGSUS_DATA_INX2 2 N/A CIMMGR EMS_SES_PEGASUS_OODATA PK_EMS_SES_PEGASUS_WAFERINX 2 N/A CIMMGR EMS_SEZ_SP223_DATA EMS_SEZ_SP223_D_IX2 2 N/A CIMMGR EMS_SEZ_SP223_OODATA PK_EMS_SEZ_SP223_WAFERINX 2 N/A CIMMGR EMS_SHIBAURA_CDE80_DATA EMS_SHIBAURA_CDE80_D_IX2 2 N/A CIMMGR EMS_SHIBAURA_CDE80_OODATA PK_EMS_SHIBAURA_CDE80_INX 2 N/A CIMMGR EMS_TEL_8S_DATA EMS_TEL_8S_D_IX2 2 N/A CIMMGR EMS_TEL_8S_OODATA PK_EMS_TEL_8S_WAFERINX 2 N/A CIMMGR EMS_TEL_ACT8_DATA EMS_TEL_ACT8_D_IX2 2 N/A CIMMGR EMS_TEL_ACT8_OODATA PK_EMS_TEL_ACT8_WAFERINX 2 N/A CIMMGR EMS_TEL_DRM_DATA EMS_TEL_DRM_D_IX2 2 N/A CIMMGR EMS_TEL_DRM_OODATA PK_EMS_TEL_DRM_WAFERINX 2 N/A CIMMGR EMS_TEL_FURNANCE_DATA EMS_TEL_FURNANCE_D_IX2 2 N/A CIMMGR EMS_TEL_FURNANCE_OODATA PK_EMS_TEL_FURNANCE_WAFERINX 2 N/A CIMMGR EMS_TEL_FURNANCE_PLUS_DATA EMS_TEL_FURNANCE_PLUS_D_IX2 2 N/A CIMMGR EMS_TEL_FURNANCE_PLUS_OODATA PK_EMS_TEL_FURNANCE_PLUS_INX 2 N/A CIMMGR EMS_TEL_GCIB_DATA EMS_TEL_GCIB_D_IX2 2 N/A CIMMGR EMS_TEL_MARK8_DATA EMS_TEL_MARK8_D_IX2 2 N/A CIMMGR EMS_TEL_MARK8_OODATA PK_EMS_TEL_MARK8_WAFERINX 2 N/A CIMMGR EMS_TEL_MB2_DATA EMS_TEL_MB2_D_IX2 2 N/A CIMMGR EMS_TEL_MB2_OODATA PK_EMS_TEL_MB2_WAFERINX 2 N/A CIMMGR EMS_TEL_UNITYEP_DATA EMS_TEL_UNITYEP_D_IX2 2 N/A CIMMGR EMS_TEL_UNITYEP_OODATA PK_EMS_TEL_UNITYEP_WAFERINX 2 N/A CIMMGR EMS_USHIO_UV_DATA EMS_USHIO_UV_D_IX2 2 N/A CIMMGR EMS_VARIAN_VIISTA810_DATA EMS_VARIAN_VIISTA810_D_IX2 2 N/A CIMMGR WSS_RESULT_HISTORY WSS_RESULT_HISTORY_INX1 3 VALID APCDEV APC_NIKON_SPEC_HIS_TABLE INX_APC_NIKON_HIS_TABLE 3 VALID APCDEV APC_NIKON_SPEC_TABLE PK_APC_NIKON_SPEC_TABLE 3 VALID APCDEV APC_OFFSET_NIKON PK_APC_OFFSET_NIKON 3 VALID APCDEV OVL_PRODUCTION_DATA_NIKON INX_OVL_PRODUCTION_DATA_NIKON 3 VALID APCDEV PROCESS_CONDITION_NIKON INX_PROCESS_CONDITION_NIKON 3 VALID APCDEV SCANNER_STATUS_NIKON PK_SCANNER_STATUS_NIKON 3 VALID
A24: 无效对象检查 | B24: DBINVALIDOBJECT
A25: 索引失效检查 | B25: DBINVALIDINDEX
A26: SEQUENCE设置检查 | B26: DBSEQUENCE | C26: SEQUENCE_OWNER CNT_LESS_200 ------------------------------ ------------ CIMMGR 35 MCSMGR 24 GSMADMIN_INTERNAL 16 WSSAPP 1 RLTDEV 1 RTDUSER 1
A27: SEQUENCE使用检查 | B27: DB_SEQ_USAGE
A28: 数据库组件 | B28: DBOPTION | C28: OPTION VALUE -------------------------------------------------- ---------- Partitioning TRUE Objects TRUE Real Application Clusters FALSE Advanced replication TRUE Bit-mapped indexes TRUE Connection multiplexing TRUE Connection pooling TRUE Database queuing TRUE Incremental backup and recovery TRUE Instead-of triggers TRUE Parallel backup and recovery TRUE Parallel execution TRUE Parallel load TRUE Point-in-time tablespace recovery TRUE Fine-grained access control TRUE Proxy authentication/authorization TRUE Change Data Capture TRUE Plan Stability TRUE Online Index Build TRUE Coalesce Index TRUE Managed Standby TRUE Materialized view rewrite TRUE Database resource manager TRUE Spatial TRUE Automatic Storage Management FALSE Export transportable tablespaces TRUE Transparent Application Failover TRUE Fast-Start Fault Recovery TRUE Sample Scan TRUE Duplexed backups TRUE Java TRUE OLAP Window Functions TRUE Block Media Recovery TRUE Fine-grained Auditing TRUE Application Role TRUE Enterprise User Security TRUE Oracle Data Guard TRUE Oracle Label Security FALSE OLAP TRUE Basic Compression TRUE Join index TRUE Trial Recovery TRUE Advanced Analytics TRUE Online Redefinition TRUE Streams Capture TRUE File Mapping TRUE Block Change Tracking TRUE Flashback Table TRUE Flashback Database TRUE Transparent Data Encryption TRUE Backup Encryption TRUE Unused Block Compression TRUE Oracle Database Vault FALSE Result Cache TRUE SQL Plan Management TRUE SecureFiles Encryption TRUE Real Application Testing TRUE Flashback Data Archive TRUE DICOM TRUE Active Data Guard TRUE Server Flash Cache TRUE Advanced Compression TRUE XStream TRUE Deferred Segment Creation TRUE Unified Auditing FALSE Management Database FALSE I/O Server FALSE ASM Proxy Instance FALSE Exadata Discovery TRUE Data Mining TRUE Global Data Services TRUE Adaptive Execution Plans TRUE Table Clustering TRUE Zone Maps TRUE Real Application Security TRUE Privilege Analysis TRUE Data Redaction TRUE Cross Transportable Backups TRUE Cache Fusion Lock Accelerator TRUE Snapshot time recovery TRUE Heat Map TRUE Automatic Data Optimization TRUE Transparent Sensitive Data Protection TRUE In-Memory Column Store TRUE Advanced Index Compression TRUE In-Memory Aggregation TRUE Centrally Managed User TRUE
A29: 功能特性 | B29: DBFEATURES | C29: NAME VERSION LAST_USAGE_DATE ------------------------------------------------------------ --------------- -------------------- Character Set 19.0.0.0.0 21-JUL-25 Deferred Segment Creation 19.0.0.0.0 21-JUL-25 Locally Managed Tablespaces (system) 19.0.0.0.0 21-JUL-25 Locally Managed Tablespaces (user) 19.0.0.0.0 21-JUL-25 Automatic SGA Tuning 19.0.0.0.0 21-JUL-25 Oracle Managed Files 19.0.0.0.0 21-JUL-25 Partitioning (system) 19.0.0.0.0 21-JUL-25 Recovery Area 19.0.0.0.0 21-JUL-25 Logfile Multiplexing 19.0.0.0.0 21-JUL-25 Duplicate Db from Active Db using BackupSet 19.0.0.0.0 21-JUL-25 Resource Manager 19.0.0.0.0 21-JUL-25 Traditional Audit 19.0.0.0.0 21-JUL-25 Unified Audit 19.0.0.0.0 21-JUL-25 Automatic Maintenance - Optimizer Statistics Gathering 19.0.0.0.0 21-JUL-25 Automatic Maintenance - Space Advisor 19.0.0.0.0 21-JUL-25 Automatic Maintenance - SQL Tuning Advisor 19.0.0.0.0 21-JUL-25 Automatic Segment Space Management (system) 19.0.0.0.0 21-JUL-25 Automatic Segment Space Management (user) 19.0.0.0.0 21-JUL-25 Automatic SQL Execution Memory 19.0.0.0.0 21-JUL-25 Automatic Undo Management 19.0.0.0.0 21-JUL-25 Real-Time SQL Monitoring 19.0.0.0.0 21-JUL-25 SQL Tuning Set (system) 19.0.0.0.0 21-JUL-25 Automatic SQL Tuning Advisor 19.0.0.0.0 21-JUL-25 SecureFiles (user) 19.0.0.0.0 21-JUL-25 SecureFiles (system) 19.0.0.0.0 21-JUL-25 LOB 19.0.0.0.0 21-JUL-25 Adaptive Plans 19.0.0.0.0 21-JUL-25 Automatic Reoptimization 19.0.0.0.0 21-JUL-25 SQL Plan Directive 19.0.0.0.0 21-JUL-25 Oracle Utility External Table (ORACLE_LOADER) 19.0.0.0.0 21-JUL-25 Instance Caging 19.0.0.0.0 21-JUL-25 Server Parameter File 19.0.0.0.0 21-JUL-25 Statistics Advisor 19.0.0.0.0 21-JUL-25 Oracle Java Virtual Machine (system) 19.0.0.0.0 21-JUL-25
A30: 用户临期检查 | B30: DB_EXPIR_USER
A31: PROFILE密码函数设置 | B31: DB_PASSWORD_VERIF | C31: PROFILE LIMIT -------------------- ------------------------------ DEFAULT NULL
A32: DBA权限用户检查 | B32: DBDBAPRIV | C32: GRANTEE GRANTED_ROLE ADMIN_OPTION ------------------------------ --------------- -------------------- SYS DBA YES SYSTEM DBA YES
A33: SYSDBA权限用户检查 | B33: DBSYSDBA
A34: 数据库审计空间检查 | B34: DBAUDITSEGMENT | C34: SEGMENT_NAME SIZE_IN_MEGABYTES TABLESPACE_NAME --------------- ----------------- ------------------------------ AUD$ 1280.00 AUDIT_TS FGA_LOG$ .06 SYSTEM
A35: 数据库审计对象检查 | B35: DBAUDITCONT | C35: COUNT(*) -------------------- .000
A36: 业务使用系统表空间检查 | B36: DB_NOSYS_IN_SYSTEM | C36: OWNER TABLESPACE_NAME SEGMENT_NAME SEGMENT_TYPE ------------------------------ ------------------------------ ------------------------------ ------------------------------ GSMADMIN_INTERNAL SYSTEM SHARD_TS TABLE GSMADMIN_INTERNAL SYSTEM SYS_C00946932 INDEX
A37: Recovery区使用检查 | B37: DBRECOVERYDEST | C37: NAME SPACE_LIMIT SPACE_USED SPACE_RECLAIMABLE NUMBER_OF_FILES CON_ID ---------------------------------------- ---------------- ---------------- ----------------- ---------------- -------------------- /apc2db_arc/flashback/apc2db 322,122,547,200 26,689,536 0 1 .000
A38: 闪回区使用 | B38: DBFLASHRECOVERYUSEAGE | C38: FILE_TYPE PERCENT_SPACE_USED PERCENT_SPACE_RECLAIMABLE NUMBER_OF_FILES CON_ID ---------------------------------------- ------------------ ------------------------- ---------------- -------------------- CONTROL FILE 91 0 0 .000 REDO LOG 0 0 0 .000 ARCHIVED LOG 0 0 0 .000 BACKUP PIECE 0 0 1 .000 IMAGE COPY 0 0 0 .000 FLASHBACK LOG 0 0 0 .000 FOREIGN ARCHIVED LOG 0 0 0 .000 AUXILIARY DATAFILE COPY 0 0 0 .000
A39: 错误口令登录锁定检查 | B39: DBPRODUCTUSERFAILEDLOGIN | C39: USERNAME PROFILE RESOURCE_NAME RESOURCE_T LIMIT ------------------------------ -------------------- ------------------------------ ---------- ------------------------------ SPLUNKAUDIT DEFAULT FAILED_LOGIN_ATTEMPTS PASSWORD UNLIMITED ORAAUD DEFAULT FAILED_LOGIN_ATTEMPTS PASSWORD UNLIMITED EAPDISSCS DEFAULT FAILED_LOGIN_ATTEMPTS PASSWORD UNLIMITED PERFSTAT DEFAULT FAILED_LOGIN_ATTEMPTS PASSWORD UNLIMITED DPA4ORACLE DEFAULT FAILED_LOGIN_ATTEMPTS PASSWORD UNLIMITED ITILUSER DEFAULT FAILED_LOGIN_ATTEMPTS PASSWORD UNLIMITED APCDEV DEFAULT FAILED_LOGIN_ATTEMPTS PASSWORD UNLIMITED WSSAPP DEFAULT FAILED_LOGIN_ATTEMPTS PASSWORD UNLIMITED AMSAPP DEFAULT FAILED_LOGIN_ATTEMPTS PASSWORD UNLIMITED EAPDEV DEFAULT FAILED_LOGIN_ATTEMPTS PASSWORD UNLIMITED F2ISSUETAG DEFAULT FAILED_LOGIN_ATTEMPTS PASSWORD UNLIMITED MCSAPP DEFAULT FAILED_LOGIN_ATTEMPTS PASSWORD UNLIMITED F1MCSAPP DEFAULT FAILED_LOGIN_ATTEMPTS PASSWORD UNLIMITED RLTDEV DEFAULT FAILED_LOGIN_ATTEMPTS PASSWORD UNLIMITED CIMRPT DEFAULT FAILED_LOGIN_ATTEMPTS PASSWORD UNLIMITED SCSAPP DEFAULT FAILED_LOGIN_ATTEMPTS PASSWORD UNLIMITED CIMMGR DEFAULT FAILED_LOGIN_ATTEMPTS PASSWORD UNLIMITED RTDUSER DEFAULT FAILED_LOGIN_ATTEMPTS PASSWORD UNLIMITED EAPQUERY DEFAULT FAILED_LOGIN_ATTEMPTS PASSWORD UNLIMITED RCPAPP DEFAULT FAILED_LOGIN_ATTEMPTS PASSWORD UNLIMITED PERFSTAT9I DEFAULT FAILED_LOGIN_ATTEMPTS PASSWORD UNLIMITED VCSUSER DEFAULT FAILED_LOGIN_ATTEMPTS PASSWORD UNLIMITED F2REPUSER DEFAULT FAILED_LOGIN_ATTEMPTS PASSWORD UNLIMITED YMSEAP2 DEFAULT FAILED_LOGIN_ATTEMPTS PASSWORD UNLIMITED EMSAPP DEFAULT FAILED_LOGIN_ATTEMPTS PASSWORD UNLIMITED ALSAPP DEFAULT FAILED_LOGIN_ATTEMPTS PASSWORD UNLIMITED CIMCFG DEFAULT FAILED_LOGIN_ATTEMPTS PASSWORD UNLIMITED PSCAPP DEFAULT FAILED_LOGIN_ATTEMPTS PASSWORD UNLIMITED MESUSER DEFAULT FAILED_LOGIN_ATTEMPTS PASSWORD UNLIMITED EAPSA DEFAULT FAILED_LOGIN_ATTEMPTS PASSWORD UNLIMITED RMSAPP DEFAULT FAILED_LOGIN_ATTEMPTS PASSWORD UNLIMITED RTDELT DEFAULT FAILED_LOGIN_ATTEMPTS PASSWORD UNLIMITED MCSMGR SESS_100 FAILED_LOGIN_ATTEMPTS PASSWORD DEFAULT
A40: 病毒勒索攻击隐患检查 | B40: DBVIRSCHECK
...

Sheet INST
A1: 实例名 | B1: INSTNAME | C1: racdb1 | D1: racdb2
A2: 数据库负载 | B2: LOADPROFILE | C2: Load Profile Per Second Per Transaction Per Exec Per Call ~~~~~~~~~~~~~~~ --------------- --------------- --------- --------- DB Time(s): 0.0 0.0 0.00 0.01 DB CPU(s): 0.0 0.0 0.00 0.00 Background CPU(s): 0.0 0.5 0.02 0.00 Redo size (bytes): 31,111,576.3 36,932.7 Logical read (blocks): 73.9 1,731.3 Block changes: 7.2 169.1 Physical read (blocks): 0.0 0.1 Physical write (blocks): 0.6 14.3 Read IO requests: 0.0 0.1 Write IO requests: 0.3 6.0 Read IO (MB): 0.0 0.0 Write IO (MB): 0.0 0.1 IM scan rows: 0.0 0.0 Session Logical Read IM: 0.0 0.0 User calls: 0.2 4.6 Parses (SQL): 1.1 25.1 Hard parses (SQL): 0.0 0.9 SQL Work Area (MB): 0.0 0.3 Logons: 30.0 0.1 User logons: 0.0 0.0 Executes (SQL): 1.1 25.9 Rollbacks: 0.0 0.9 Transactions: 0.0 | D2: Load Profile Per Second Per Transaction Per Exec Per Call ~~~~~~~~~~~~~~~ --------------- --------------- --------- --------- DB Time(s): 0.0 0.0 0.00 0.01 DB CPU(s): 0.0 0.0 0.00 0.00 Background CPU(s): 0.0 0.5 0.02 0.00 Redo size (bytes): 31,111,576.3 36,932.7 Logical read (blocks): 73.9 1,731.3 Block changes: 7.2 169.1 Physical read (blocks): 0.0 0.1 Physical write (blocks): 0.6 14.3 Read IO requests: 0.0 0.1 Write IO requests: 0.3 6.0 Read IO (MB): 0.0 0.0 Write IO (MB): 0.0 0.1 IM scan rows: 0.0 0.0 Session Logical Read IM: 0.0 0.0 User calls: 0.2 4.6 Parses (SQL): 1.1 25.1 Hard parses (SQL): 0.0 0.9 SQL Work Area (MB): 0.0 0.3 Logons: 30.0 0.1 User logons: 0.0 0.0 Executes (SQL): 1.1 25.9 Rollbacks: 0.0 0.9 Transactions: 0.0
A3: 数据库运行效率 | B3: INSTEFFICIENCY | C3: Instance Efficiency Percentages (Target 100%) ~~~~~~~~~~~~~~~~~~~~~~~~~~~~~~~~~~~~~~~~~~~~~ Buffer Nowait %: 60.00 Redo NoWait %: 60.00 Buffer Hit %: 60.00 In-memory Sort %: 100.00 Library Hit %: 65.94 Soft Parse %: 66.55 Execute to Parse %: 2.81 Latch Hit %: 99.93 Parse CPU to Parse Elapsd %: 53.85 % Non-Parse CPU: 99.95 Flash Cache Hit %: 0.00 | D3: Instance Efficiency Percentages (Target 100%) ~~~~~~~~~~~~~~~~~~~~~~~~~~~~~~~~~~~~~~~~~~~~~ Buffer Nowait %: 60.00 Redo NoWait %: 60.00 Buffer Hit %: 60.00 In-memory Sort %: 100.00 Library Hit %: 65.94 Soft Parse %: 66.55 Execute to Parse %: 2.81 Latch Hit %: 99.93 Parse CPU to Parse Elapsd %: 53.85 % Non-Parse CPU: 99.95 Flash Cache Hit %: 0.00
A4: 游标>300M检查 | B4: DB_CURSORMEM
A5: Top等待 | B5: TOPEVENT | C5: Top 10 Foreground Events by Total Wait Time ~~~~~~~~~~~~~~~~~~~~~~~~~~~~~~~~~~~~~~~~~~~ Total Wait Avg % DB Wait Event Waits Time (sec) Wait time Class ------------------------------ ----------- ---------- --------- ------ -------- SQL*Net message from dblink 1,310 7.3 5.55ms 65.1 Network DB CPU 3.9 35.3 log file sync 9 .4 46.00ms 3.7 Commit SQL*Net break/reset to client 524 .1 228.04us 1.1 Applicat SQL*Net break/reset to dblink 262 0 16.21us .0 Applicat PGA memory operation 69 0 16.13us .0 Other SQL*Net message to dblink 786 0 922.39ns .0 Network SQL*Net message to client 786 0 745.55ns .0 Network Disk file operations I/O 1 0 7.00us .0 User I/O ADR block file read 0 0 .0 Other | D5: Top 10 Foreground Events by Total Wait Time ~~~~~~~~~~~~~~~~~~~~~~~~~~~~~~~~~~~~~~~~~~~ Total Wait Avg % DB Wait Event Waits Time (sec) Wait time Class ------------------------------ ----------- ---------- --------- ------ -------- SQL*Net message from dblink 1,310 7.3 5.55ms 65.1 Network DB CPU 3.9 35.3 log file sync 9 .4 46.00ms 3.7 Commit SQL*Net break/reset to client 524 .1 228.04us 1.1 Applicat SQL*Net break/reset to dblink 262 0 16.21us .0 Applicat PGA memory operation 69 0 16.13us .0 Other SQL*Net message to dblink 786 0 922.39ns .0 Network SQL*Net message to client 786 0 745.55ns .0 Network Disk file operations I/O 1 0 7.00us .0 User I/O ADR block file read 0 0 .0 Other
A6: Top SQL(耗时) | B6: TOPSQLBYELAPSTIME
A7: 数据库PSU | B7: DBPSU
A8: 数据库补丁 | B8: DBPATCH
A9: 监听检查 | B9: DBLSNRINFO
A10: 数据库参数 | B10: DBPARAMETER
A11: 参数文件 | B11: DB_PARAMETER_FILE
A12: 归档切换检查 | B12: DBREDOSWITCH | C12: DT DY Total h0 h1 h2 h3 h4 h5 h6 h7 h8 h9 h10 h11 h12 h13 h14 h15 h16 h17 h18 h19 h20 h21 h22 h23 ---------- ------- ----- --- --- --- --- --- --- --- --- --- --- --- --- --- --- --- --- --- --- --- --- --- --- --- --- 2023-03-04 Sat 114 23 13 32 31 35 45 20 30 20 33 45 0 0 0 0 0 0 0 0 0 0 0 2023-03-06 Mon 1 1 0 0 0 0 0 0 0 0 0 0 0 0 0 0 0 0 0 0 0 0 0 0 0 2023-03-08 Wed 1 1 0 0 0 0 0 0 0 0 0 0 0 0 0 0 0 0 0 0 0 0 0 0 0 2023-03-10 Fri 1 0 0 0 0 0 0 0 0 1 0 0 0 0 0 0 0 0 0 0 0 0 0 0 0 2023-03-12 Sun 1 0 0 0 0 0 0 1 0 0 0 0 0 0 0 0 0 0 0 0 0 0 0 0 0 2023-03-14 Tue 1 0 0 0 0 0 0 0 0 0 1 0 0 0 0 0 0 0 0 0 0 0 0 0 0 2023-03-16 Thu 1 0 0 0 0 0 0 0 0 0 0 0 1 0 0 0 0 0 0 0 0 0 0 0 0 2023-03-18 Sat 1 0 0 0 0 0 0 0 0 0 0 0 0 0 0 0 0 1 0 0 0 0 0 0 0 | D12: DT DY Total h0 h1 h2 h3 h4 h5 h6 h7 h8 h9 h10 h11 h12 h13 h14 h15 h16 h17 h18 h19 h20 h21 h22 h23 ---------- ------- ----- --- --- --- --- --- --- --- --- --- --- --- --- --- --- --- --- --- --- --- --- --- --- --- --- 2023-03-04 Sat 114 23 13 32 31 35 45 20 30 20 33 45 0 0 0 0 0 0 0 0 0 0 0 2023-03-06 Mon 1 1 0 0 0 0 0 0 0 0 0 0 0 0 0 0 0 0 0 0 0 0 0 0 0 2023-03-08 Wed 1 1 0 0 0 0 0 0 0 0 0 0 0 0 0 0 0 0 0 0 0 0 0 0 0 2023-03-10 Fri 1 0 0 0 0 0 0 0 0 1 0 0 0 0 0 0 0 0 0 0 0 0 0 0 0 2023-03-12 Sun 1 0 0 0 0 0 0 1 0 0 0 0 0 0 0 0 0 0 0 0 0 0 0 0 0 2023-03-14 Tue 1 0 0 0 0 0 0 0 0 0 1 0 0 0 0 0 0 0 0 0 0 0 0 0 0 2023-03-16 Thu 1 0 0 0 0 0 0 0 0 0 0 0 1 0 0 0 0 0 0 0 0 0 0 0 0 2023-03-18 Sat 1 0 0 0 0 0 0 0 0 0 0 0 0 0 0 0 0 1 0 0 0 0 0 0 0
A13: 数据库日志检查 | B13: DBERRLOG
